Workbook

Sheet Pucusana
A1: Encuesta | B1: Nombre_Encuestador | C1: Fecha_Encuesta | D1: Nombre_Pescador | E1: DNI | F1: Años_Pesca | G1: Años_Altura | H1: Distrito_Vivienda | I1: Puerto_Zarpe | J1: Puerto_Arribo | K1: Fecha_Nacimiento | L1: Edad | M1: Sexo | N1: Estado_Civil | O1: Grado_Instruccion | P1: Alfabeto | Q1: Seguro_Salud | R1: Rol_Pescador | S1: OSPA | T1: Nombre_OSPA | U1: Otra_Pesca | V1: Arte_Costera1 | W1: Rec_Costero1 | X1: Arte_Costera2 | Y1: Rec_Costero2 | Z1: Arte_Costera3 | AA1: Rec_Costero3 | AB1: Alterna_Pesca | AC1: Actividad_Alterna | AD1: Personas_Dependientes | AE1: Numero_hijos | AF1: Pareja | AG1: Actividades_Pareja | AH1: FamiliaDirecta_Pesca | AI1: Rol_Familiares | AJ1: Genero_Opotunidades | AK1: GenOpor_No | AL1: Genero_Pago | AM1: GenPago_No | AN1: Num_Embarcaciones | AO1: Embarcacion_Propia | AP1: Nombre1_EmbarcacionAltura | AQ1: Matricula_1 | AR1: SISESAT_1 | AS1: Radiobaliza_1 | AT1: PTH_1 | AU1: TN_Bodega_1 | AV1: Nombre2_EmbarcacionAltura | AW1: Matricula_2 | AX1: SISESAT_2 | AY1: Radiobaliza_2 | AZ1: PTH_2 | BA1: TN_Bodega_2 | BB1: Galones_Combustible | BC1: Arte_1 | BD1: Num_Tripulantes1 | BE1: Edades_Tripulantes1 | BF1: Nacionalidad_Trip1 | BG1: Recurso_1 | BH1: Carnada1 | BI1: Temporada1 | BJ1: Viajes_Temporada1 | BK1: Detalles_Arte1 | BL1: Dias_Faena1 | BM1: Horas_Efectivas1 | BN1: Lances_Faena1 | BO1: Kg_Lance1 | BP1: Kg_Faena1 | BQ1: Venta_Recurso1 | BR1: Precio_Kg1 | BS1: Arte_2 | BT1: Num_Tripulantes2 | BU1: Edades_Tripulantes2 | BV1: Nacionalidad_Trip2 | BW1: Recurso_2 | BX1: Carnada2 | BY1: Temporada2 | BZ1: Viajes_Temporada2 | CA1: Detalles_Arte2 | CB1: Dias_Faena2 | CC1: Horas_Efectivas2 | CD1: Lances_Faena2 | CE1: Kg_Lance2 | CF1: Kg_Faena2 | CG1: Venta_Recurso2 | CH1: Precio_Kg2 | CI1: Arte_3 | CJ1: Recurso_3 | CK1: Carnada3 | CL1: Temporada3 | CM1: Viajes_Temporada3 | CN1: Detalles_Arte3 | CO1: Dias_Faena3 | CP1: Horas_Efectivas3 | CQ1: Lances_Faena3 | CR1: Captura_Lance3 | CS1: Captura_Faena3 | CT1: Venta_Recurso3 | CU1: Precio_Kg3 | CV1: Observaciones | CW1: Telefono
A2: KD-PUCUSANA-001 | B2: Kelly Diaz | C2: 45883 | D2: Manuel Jose Avalos Carrillo | E2: 42939396 | F2: 27 | G2: 27 | H2: Pucusana | I2: Pucusana | J2: Pucusana, Pisco, San Andrés | K2: 23182 | L2: =DATEDIF(K2, DATE(2025,8,29), "Y") -> 62 | M2: M | N2: Casado/Conviviente | O2: Secundaria | P2: si | Q2: si | R2: Armador, Patrón | S2: si | T2: Asociación Gremio de Pescadores de Pucusana | U2: no | V2: NA | W2: NA | X2: NA | Y2: NA | Z2: NA | AA2: NA | AB2: si | AC2: Secretario del Gremio | AD2: 4 | AE2: 3 | AF2: si | AG2: Ama de casa | AH2: no | AI2: NA | AJ2: no | AK2: La fuerza fisica natural no es la misma | AL2: si | AM2: NA | AN2: 1 | AO2: si | AP2: EL GRAN SHADAI | AQ2: CO-05274-BM | AR2: no | AS2: no | AT2: si | AU2: 5 | AV2: NA | AW2: NA | AX2: NA | AY2: NA | AZ2: NA | BA2: NA | BB2: 68-85 | BC2: Cortina superficial | BD2: 4 | BE2: 25-40 | BF2: Peruana | BG2: Bonito | BH2: no | BI2: Octubre-Mayo | BJ2: 40 | BK2: #paños: 10, cocada: 4 pulgadas, malla 4.5 x ?? M | BL2: 7 | BM2: 4 | BN2: 12-15 | BO2: 1000-2000 | BP2: 6000 | BQ2: Acopiador | BR2: 1-10 | BS2: Trampa Ovas | BT2: 3 | BU2: 25-40 | BV2: Peruana | BW2: Ova | BX2: no | BY2: Octubre-Noviembre | BZ2: 2-3 | CA2: Esteras y palmeras. Usa 20-21 trampas, en 3 filas de 5. Dimensiones de trampa 3x1.5 metros | CB2: 30 | CC2: 72-96 | CD2: 10 | CE2: 200-500 | CF2: 1400 | CG2: Acopiador | CH2: 37-40 | CI2: no | CJ2: NA | CK2: NA | CL2: NA | CM2: NA | CN2: NA | CO2: NA | CP2: NA | CQ2: NA | CR2: NA | CS2: NA | CT2: NA | CU2: NA | CV2: Precio (kg) de ova con ojo: 5 soles. Temperatura para la ova debe ser entre 18-20 C. Si el agua esta fria, la trampa se queda en el agua por 4 dias; si esta caliente, por 2.5 a 3 dias | CW2: 995 555 047
A3: KD-PUCUSANA-002 | B3: Kelly Diaz | C3: 45883 | D3: Rene Yupanqui Mendoza | E3: 04636818 | F3: 34 | G3: 34 | H3: Pucusana | I3: Pucusana | J3: Pucusana, Atico, La Planchada, Ancón, Marcona | K3: 24667 | L3: =DATEDIF(K3, DATE(2025,8,29), "Y") -> 58 | M3: M | N3: Casado/Conviviente | O3: Secundaria | P3: si | Q3: si | R3: Armador, Patrón | S3: no | T3: NA | U3: no | V3: NA | W3: NA | X3: NA | Y3: NA | Z3: NA | AA3: NA | AB3: no | AC3: NA | AD3: 1 | AE3: 3 | AF3: si | AG3: Administra la embarcación y el recurso | AH3: si | AI3: 1 hijo: dueño de lancha en Ilo | AJ3: si | AK3: NA | AL3: no | AM3: Costumbre y opiniones antiguas | AN3: 2 | AO3: si | AP3: FAVIMAR | AQ3: CO-65441-BM | AR3: no | AS3: si | AT3: si | AU3: 5 | AV3: FAVIMAR I | AW3: PT-40356-BM | AX3: no | AY3: no | AZ3: si | BA3: 6 | BB3: 200-250 | BC3: Pinta Potera | BD3: 4 | BE3: 20-40 | BF3: Peruana | BG3: Pota | BH3: no | BI3: Enero-Diciembre | BJ3: 24 | BK3: 2 viajes/mes | BL3: 4-5 | BM3: NS | BN3: NS | BO3: 2000 | BP3: 8000 | BQ3: Acopiador | BR3: 1.5-2 | BS3: Cortina superficial | BT3: 4 | BU3: 20-40 | BV3: Peruana | BW3: Bonito | BX3: no | BY3: Enero-Diciembre | BZ3: 24 | CA3: #paños: 6, cocada: 4 pulgadas, malla 4.5x9 metros | CB3: 6 | CC3: 3 | CD3: 15-18 | CE3: 200-1000 | CF3: 3000-4000 | CG3: Acopiador | CH3: 5 | CI3: Trampa Ovas | CJ3: Ova | CK3: no | CL3: Noviembre-Febrero | CM3: 2-3 | CN3: Esteras con palmeras, a veces zargazo. Usa 18 trampas, en 6 filas de 3. Dimension de tampa 3x2 m | CO3: 30-40 | CP3: 72 | CQ3: 10 | CR3: 80-150 | CS3: 1000-1500 | CT3: Acopiador | CU3: 30 | CV3: Zona: Ova (70-80 millas fuera de Marcona y La Planchada); Bonito (60 millas fuera); Pota (60-200 millas fuera de Callao a Pucusana). Precio (kg) de ova con ojo: 5-10 soles. Pescador cree que ova con ojo es destinada a la sierra del Peru o a Bolivia. Hace 2 años, la ova costaba S/.50 por kg. Temperatura necesaria para Perico: 20-22 C. Comenta que SISESAT no es necesario, es caro y el pago no es mensual; si se malogra, deben regresar. Pucusana necesita un desembarcadero, ya que es el punto de arribo preferido por muchos embarcadores ya que el precio es mas alto aqui, y hay mas seguridad y tranquilidad que en callao. | CW3: 908 619 439 | CY3: Ova (70-80 millas fuera de Marcona y La Planchada)
A4: KD-PUCUSANA-003 | B4: Kelly Diaz | C4: 45884 | D4: Adolfo Climber Molina Cespedes | E4: 80006544 | F4: 18 | G4: 16 | H4: Pucusana | I4: Pucusana | J4: Pucusana, Chimbote, Ilo | K4: 28344 | L4: =DATEDIF(K4, DATE(2025,8,29), "Y") -> 48 | M4: M | N4: Casado/Conviviente | O4: Secundaria | P4: si | Q4: Privado | R4: Patrón | S4: si | T4: Asociación Gremio de Pescadores de Pucusana | U4: no | V4: NA | W4: NA | X4: NA | Y4: NA | Z4: NA | AA4: NA | AB4: si | AC4: Turismo | AD4: 3 | AE4: 2 | AF4: si | AG4: Mantenimiento en la isla de Pucusana | AH4: no | AI4: NA | AJ4: si | AK4: NA | AL4: si | AM4: NA | AN4: NS | AO4: no | AP4: DON VICTOR | AQ4: NS | AR4: si | AS4: no | AT4: si | AU4: 8 | AV4: JUANITA | AW4: NS | AX4: si | AY4: no | AZ4: no | BA4: 8 | BB4: 250-300 | BC4: Espinel | BD4: 4 | BE4: 30-40 | BF4: Peruana | BG4: Perico | BH4: si, pota, lisa, tamborin | BI4: Enero-Marzo | BJ4: 4-8 | BK4: Linea madre: 17 millas. #anzuelos: 2500. 1 anzuelo/linea. Calibre: 5 | BL4: 15-30 | BM4: 4-5 | BN4: 10-15 | BO4: 1500-2000 | BP4: 10000 | BQ4: Acopiador | BR4: 10-12 | BS4: Trampa Ovas | BT4: 3 | BU4: 30-40 | BV4: Peruana | BW4: Ova | BX4: no | BY4: Septiembre-Enero | BZ4: 3-4 | CA4: Esteras y manta, con palmeras. Usa 20 trampas, en 4 filas de 5. Dimensiones de trampa 3x2 metros | CB4: 30-45 | CC4: 72 | CD4: 10-12 | CE4: 100-500 | CF4: 3000-5000 | CG4: Acopiador | CH4: 30-35 | CI4: Cortina Superficial | CJ4: Bonito | CK4: no | CL4: Enero-Marzo | CM4: 20-24 | CN4: #paños: 10, cocada: 4 pulgadas, malla 6x500 metros | CO4: 7 | CP4: 2 | CQ4: 20-25 | CR4: 20-5000 | CS4: 5000-10000 | CT4: Acopiador | CU4: 4-7 | CV4: Zona: Ova (150-200 millas fuera de Marcona y La Planchada); Bonito (60-200 millas fuera de Pisco, Pucusana y Huacho); Perico (150 millas fuera de Paita,, Pucusana, Pisco, Ancon, Huacho, Ilo). Precio (kg) de ova con ojo: 3 soles. Para la huevera, las trampas se colocan y la embarcacion queda a la deriva. El zargazo dura 2 faenas de uso, se malogra rapido; la palmera dura 2 meses (llevan reemplazos). Si la trampa se queda 5 a 6 dias, la huevera desarrolla ojo y ya no sirve. | CW4: 967 688 205 | CY4: Ova (150-200 millas fuera de Marcona y La Planchada)
A5: KD-PUCUSANA-004 | B5: Kelly Diaz | C5: 45884 | D5: Jose Carlos Florian Peña | E5: 42953858 | F5: 22 | G5: 22 | H5: Pucusana | I5: Pucusana | J5: Pucusana, Ancón, Pisco | K5: 19889 | L5: =DATEDIF(K5, DATE(2025,8,29), "Y") -> 71 | M5: M | N5: Casado/Conviviente | O5: Secundaria | P5: si | Q5: Privado | R5: Armador, Patrón | S5: si | T5: Asociación Gremio de Pescadores de Pucusana | U5: no | V5: NA | W5: NA | X5: NA | Y5: NA | Z5: NA | AA5: NA | AB5: no | AC5: NA | AD5: 1 | AE5: 1 | AF5: si | AG5: Enfermera | AH5: no | AI5: NA | AJ5: si | AK5: NA | AL5: si | AM5: NA | AN5: 1 | AO5: si | AP5: JOSEPH SCHALOOM II | AQ5: CO-37277-BM | AR5: no | AS5: no | AT5: si | AU5: 6.19 | AV5: NA | AW5: NA | AX5: NA | AY5: NA | AZ5: NA | BA5: NA | BB5: 300-340 | BC5: Cortina superficial | BD5: 4 | BE5: 25-60 | BF5: Peruana | BG5: Bonito | BH5: no | BI5: Septiembre-Abril | BJ5: 30-40 | BK5: #paños: 8-10, cocada: 4-4.5 pulgadas, malla 4.5 x 1500 m | BL5: 3-4 | BM5: 1.5-2 | BN5: 10-15 | BO5: 1000-4000 | BP5: 4000-6000 | BQ5: Acopiador | BR5: 2-5 | BS5: Espinel | BT5: 4 | BU5: 25-60 | BV5: Peruana | BW5: Perico | BX5: si, pota, caballa | BY5: Noviembre-Enero | BZ5: 3-4 | CA5: Linea madre: 9000 m. #anzuelos: 600-1000. 1 anzuelo/linea. Calibre: 5 | CB5: 6 | CC5: 3-4 | CD5: 6 | CE5: 500-1000 | CF5: 4000-5000 | CG5: Acopiador | CH5: 4-5 | CI5: Trampa Ovas | CJ5: Ova | CK5: no | CL5: Octubre-Enero | CM5: 4 | CN5: Esteras y manta con palmeras. Usa 12 trampas, en 6 filas de 2. Dimension de tampa 1.5x3 m | CO5: 25 | CP5: 72 | CQ5: 7-8 | CR5: 500-1000 | CS5: 4000-7000 | CT5: Acopiador | CU5: 24 | CV5: Zona: Ova (40 millas fuera de Marcona); Bonito (20-100 millas fuera de Marcona, Callao, Pisco); Perico (150 millas fuera de Marcona). Ova con ojo: no se compra. | CY5: Ova (40 millas fuera de Marcona)
A6: KD-PUCUSANA-005 | B6: Kelly Diaz | C6: 45884 | D6: Zacarias Juan Chavez Truevas | E6: 41845641 | F6: 20 | G6: 20 | H6: Pucusana | I6: Pucusana | J6: Pucusana | K6: 30430 | L6: =DATEDIF(K6, DATE(2025,8,29), "Y") -> 42 | M6: M | N6: Casado/Conviviente | O6: Superior Técnico | P6: si | Q6: si | R6: Armador, Patrón | S6: si | T6: Asociación Gremio de Pescadores de Pucusana | U6: no | V6: NA | W6: NA | X6: NA | Y6: NA | Z6: NA | AA6: NA | AB6: si | AC6: Entrenador de futbol | AD6: 2 | AE6: 3 | AF6: si | AG6: Turismo y Limpieza | AH6: si | AI6: 1 hijo: tripulante | AJ6: si | AK6: NA | AL6: si | AM6: NA | AN6: 3 (solo 1 opera) | AO6: si | AP6: NIÑO JESUS | AQ6: TA-60295-BM | AR6: no | AS6: no | AT6: si | AU6: 8 | AV6: NA | AW6: NA | AX6: NA | AY6: NA | AZ6: NA | BA6: NA | BB6: 200-250 | BC6: Pinta Potera | BD6: 4-5 | BE6: 25-46 | BF6: Peruana | BG6: Pota | BH6: no | BI6: Enero-Diciembre | BJ6: 24-48 | BK6: 2-4 viajes/mes | BL6: 7 | BM6: NS | BN6: NS | BO6: 500-1000 | BP6: 1000-5000 | BQ6: Acopiador | BR6: 1-4 | BS6: Pinta | BT6: 3 | BU6: 25-46 | BV6: Peruana | BW6: Bonito | BX6: no | BY6: Enero-Diciembre | BZ6: 12 | CA6: 1 viaje/mes. No es una pesca constante | CB6: 4-5 | CC6: NS | CD6: NS | CE6: 100-400 | CF6: 200-2000 | CG6: Acopiador | CH6: 5 | CI6: NA | CJ6: NA | CK6: NA | CL6: NA | CM6: NA | CN6: NA | CO6: NA | CP6: NA | CQ6: NA | CR6: NA | CS6: NA | CT6: NA | CU6: NA | CV6: Zona: Bonito (15 millas fuera de Pachacamac y Pucusana); Pota (50-170 millas fuera de Paita a Pucusana). Opina que los costos de los pescadores para participar en la pesca exploratoria deben ser cubiertos por IMARPE. El SISESAT debe tener contratos mas cortos (el minimo es de 6 meses) porque cuando quedan varados (por ejemplo, por veda) se gastan esos meses de contrato pero ellos no estan generando dinero. Sobre la ova, la ova del Peru es mas rica en nutrientes, por lo que se vende mas caro. | CW6: 959 963 258
A7: KD-PUCUSANA-006 | B7: Kelly Diaz | C7: 45884 | D7: Carlos Alfonso Navarrete La Madrid | E7: 10819413 | F7: 39 | G7: 1 | H7: Pucusana | I7: Pucusana | J7: Pucusana, Pisco, Callao | K7: 26850 | L7: =DATEDIF(K7, DATE(2025,8,29), "Y") -> 52 | M7: M | N7: Casado/Conviviente | O7: Secundaria | P7: si | Q7: Privado | R7: Armador | S7: si | T7: Asociación Gremio de Pescadores de Pucusana | U7: si | V7: Pinta | W7: bonito | X7: Cerco costero | Y7: Caballa, lorna | Z7: NA | AA7: NA | AB7: no | AC7: NA | AD7: 2 | AE7: 2 | AF7: si | AG7: Obstetra | AH7: no | AI7: NA | AJ7: si | AK7: NA | AL7: si | AM7: NA | AN7: 2 | AO7: si | AP7: MICAELA Y ADRIAN | AQ7: CO-59871-BM | AR7: no | AS7: no | AT7: si | AU7: 6 | AV7: MICAELA Y ADRIAN | AW7: PS-56767-BM | AX7: no | AY7: no | AZ7: si | BA7: 6 | BB7: 300-350 | BC7: Pinta Potera | BD7: 3-4 | BE7: 30-60 | BF7: Peruana | BG7: Pota | BH7: no | BI7: Diciembre-Junio | BJ7: 25-28 | BK7: 4 viajes/mes | BL7: 4 | BM7: NS | BN7: NS | BO7: 500-1000 | BP7: 4000-5000 | BQ7: Acopiador, minorista (chinchanos, para el mercado local compran la pota chancada) | BR7: 1-6 | BS7: NA | BT7: NA | BU7: NA | BV7: NA | BW7: NA | BX7: NA | BY7: NA | BZ7: NA | CA7: NA | CB7: NA | CC7: NA | CD7: NA | CE7: NA | CF7: NA | CG7: NA | CH7: NA | CI7: NA | CJ7: NA | CK7: NA | CL7: NA | CM7: NA | CN7: NA | CO7: NA | CP7: NA | CQ7: NA | CR7: NA | CS7: NA | CT7: NA | CU7: NA | CV7: Zona: Pota (20-150 millas fuera de Marcona y La Planchada). La pesca de la pota la realizan todo el dia, parando talvez 1 hora de vez en cuando para descansar, pero tomando turnos para que alguien siempre este atento a la muestra (1 linea siempre queda en el agua). El comprador minorista de la pota le llaman "chinchano" que compran la pota chancada para el mercado local. Sobre la ova, el sabe que las hembras liberan sus huevos debajo de la estera, y los machos su esperma por encima de la estera. La estera queda como espoonja. | CW7: 941 451 916
A8: KD-PUCUSANA-007 | B8: Kelly Diaz | C8: 45884 | D8: Ismael Porfirio Rueda Navarro | E8: 07896918 | F8: 52 | G8: 44 | H8: Pucusana | I8: Pucusana | J8: Pucusana | K8: 23359 | L8: =DATEDIF(K8, DATE(2025,8,29), "Y") -> 61 | M8: M | N8: Divorciado | O8: Secundaria | P8: si | Q8: si | R8: Armador, Patrón | S8: si | T8: Asociación Gremio de Pescadores de Pucusana | U8: si | V8: Cortina costera | W8: pejerrey | X8: NA | Y8: NA | Z8: NA | AA8: NA | AB8: no | AC8: NA | AD8: 2 | AE8: 2 | AF8: no | AG8: NA | AH8: si | AI8: 1 hijo: mantenimiento y a veces tripulante | AJ8: no | AK8: La fuerza fisica natural no es la misma | AL8: no | AM8: no se suele llevar mujeres a altura | AN8: 2 | AO8: si | AP8: ISMAEL Y LEO | AQ8: CO-39328-BM | AR8: no | AS8: no | AT8: si | AU8: 3.7 | AV8: ISMAEL Y LEO III | AW8: CO-43396-BM | AX8: no | AY8: no | AZ8: si | BA8: 6.48 | BB8: 140-270 | BC8: Cortina superficial | BD8: 3-4 | BE8: 30-40 | BF8: Peruana | BG8: Bonito | BH8: no | BI8: Octubre-Abril | BJ8: 25-28 | BK8: #paños: 10, cocada: 4 pulgadas, malla 6 x 100 m | BL8: 4-5 | BM8: 2-3 | BN8: 12-20 | BO8: 300-2000 | BP8: 3000-6000 | BQ8: Acopiador | BR8: 5 | BS8: Pinta Potera | BT8: 3-4 | BU8: 30-40 | BV8: Peruana | BW8: Pota | BX8: no | BY8: Septiembre-Junio | BZ8: 35-40 | CA8: 4 viajes/mes | CB8: 4-5 | CC8: NS | CD8: NS | CE8: 500-1000 | CF8: 4000-5000 | CG8: Acopiador | CH8: 1.8 | CI8: Trampa Ovas | CJ8: Ova | CK8: no | CL8: Septiembre-Diciembre | CM8: 3 | CN8: Esteras y manta con palmeras y manguera. Usa 12 trampas, en 4 filas de 3. Dimension de tampa 2x2.9 m | CO8: 40 | CP8: 72 | CQ8: 10-12 | CR8: 80-100 | CS8: 1000-1500 | CT8: Acopiador | CU8: 26-37 | CV8: Zona: Ova (40 millas fuera de Marcona); Bonito (40 millas fuera de Pisco y Chancay); Pota (40 millas fuera de Pisco y Chancay). Ova con ojo no se vende. La manguera es mas economica a largo plazo. La trampa se coloca al ras del agua. | CW8: 940 906 288 | CY8: Ova (40 millas fuera de Marcona)
A9: KD-PUCUSANA-008 | B9: Kelly Diaz | C9: 45884 | D9: Isaias Torrejon Fernandez | E9: 07896692 | F9: 60 | G9: 37 | H9: Pucusana | I9: Pucusana | J9: Pucusana, Salaverry, Marcona, Callao | K9: 18052 | L9: =DATEDIF(K9, DATE(2025,8,29), "Y") -> 76 | M9: M | N9: Viudo | O9: Primaria | P9: si | Q9: Privado | R9: Armador | S9: si | T9: Asociación Gremio de Pescadores de Pucusana | U9: no | V9: NA | W9: NA | X9: NA | Y9: NA | Z9: NA | AA9: NA | AB9: si | AC9: Mantenimiento | AD9: 0 | AE9: 2 | AF9: no | AG9: NA | AH9: si | AI9: 1 hijo: armador | AJ9: si | AK9: NA | AL9: si | AM9: NA | AN9: 2 | AO9: si | AP9: MI JHOMA | AQ9: CO-06461-BM | AR9: no | AS9: no | AT9: si | AU9: 4 | AV9: MI JHOMA II | AW9: CO-19588-BM | AX9: no | AY9: no | AZ9: si | BA9: 5 | BB9: 320-360 | BC9: Trampa Ovas | BD9: 3 | BE9: 30-60 | BF9: Peruana | BG9: Ova | BH9: no | BI9: Septiembre-Marzo | BJ9: 3-4 | BK9: Esteras y manta, con palmeras. Usa 15-20 trampas, en 4 filas de 5. Dimensiones de trampa 3x2 metros | BL9: 30 | BM9: 72 | BN9: 10 | BO9: 300-450 | BP9: 1000-2000 | BQ9: Acopiador | BR9: 42 | BS9: NA | BT9: NA | BU9: NA | BV9: NA | BW9: NA | BX9: NA | BY9: NA | BZ9: NA | CA9: NA | CB9: NA | CC9: NA | CD9: NA | CE9: NA | CF9: NA | CG9: NA | CH9: NA | CI9: NA | CJ9: NA | CK9: NA | CL9: NA | CM9: NA | CN9: NA | CO9: NA | CP9: NA | CQ9: NA | CR9: NA | CS9: NA | CT9: NA | CU9: NA | CV9: Zona: Ova (100-120 millas fuera de Atico, Pisco, Marcona, Bayovar). Precio (kg) de ova con ojo: 5 soles. 70 a 80 kg de 1000 a 2000 kg del total, son ovas con ojo. Palmera puede costar S/.12 c/u, llevan 250. Antes, salian a la ova por 2 a 3 semanas, pero desde hace 2 años salen mminimo 1 mes, para que sea 1 solo gasto. Es posible hacer estos viajes largos para la ova porque al recoger la ova, la salan y la dejan al sol por 1 a 2 horas. Esto hace que se reduzca el tamano y que dure mas tiempo el producto. Una vez en muelle, se echa la ova en una tina por 1 a 2 hr y vuelve a la normalidad. La estera y la manta van al nivel del agua, y luego de 15 a 20 cm va la palmera. | CW9: 995 951 601 | CY9: Ova (100-120 millas fuera de Atico, Pisco, Marcona, Bayovar)
A10: KD-PUCUSANA-009 | B10: Kelly Diaz | C10: 45884 | D10: Andres Jesus Alberto Caycho Carrillo | E10: 73478799 | F10: 3 | G10: 2 | H10: Pucusana | I10: Pucusana | J10: Pucusana | K10: 35143 | L10: =DATEDIF(K10, DATE(2025,8,29), "Y") -> 29 | M10: M | N10: Soltero | O10: Superior Universitario | P10: si | Q10: si | R10: Tripulación | S10: si | T10: Asociación Gremio de Pescadores de Pucusana | U10: no | V10: NA | W10: NA | X10: NA | Y10: NA | Z10: NA | AA10: NA | AB10: si | AC10: Integración comunitaria | AD10: 1 | AE10: 1 | AF10: no | AG10: NA | AH10: no | AI10: NA | AJ10: no | AK10: por el machismo | AL10: no | AM10: aun hay muchos pescadores machistas | AN10: NS | AO10: no | AP10: NA | AQ10: NA | AR10: NA | AS10: NA | AT10: NA | AU10: NA | AV10: NA | AW10: NA | AX10: NA | AY10: NA | AZ10: NA | BA10: NA | BB10: NS | BC10: Cerco | BD10: 4-5 | BE10: 25-35 | BF10: Peruana | BG10: Bonito | BH10: no | BI10: Noviembre-Enero | BJ10: 25-35 | BK10: no recuerda | BL10: 4-7 | BM10: 1-2 | BN10: 8-20 | BO10: 300-1000 | BP10: 4000 | BQ10: Acopiador | BR10: 2.5 | BS10: Espinel | BT10: 4 | BU10: 25-35 | BV10: Peruana | BW10: Perico | BX10: si | BY10: Noviembre-Marzo | BZ10: 5-10 | CA10: no sabe | CB10: 5-20 | CC10: 3-4 | CD10: 5-15 | CE10: 500-1000 | CF10: 2000-4000 | CG10: Acopiador | CH10: NS | CI10: NA | CJ10: NA | CK10: NA | CL10: NA | CM10: NA | CN10: NA | CO10: NA | CP10: NA | CQ10: NA | CR10: NA | CS10: NA | CT10: NA | CU10: NA | CV10: Zona: Bonito (50-60 millas fuera de Pucusana); Perico (120 millas fuera de Lima a Pucusana). Se dedica mas a la integracion comunitaria en temas marinos, enseñando a niños | CW10: 961 830 866
A11: KD-PUCUSANA-010 | B11: Kelly Diaz | C11: 45885 | D11: Segundo Luis Morales Huertas "cochecho" | E11: 03325844 | F11: 30 | G11: 30 | H11: Pucusana | I11: Pucusana | J11: Pucusana | K11: 25106 | L11: =DATEDIF(K11, DATE(2025,8,29), "Y") -> 56 | M11: M | N11: Casado/Conviviente | O11: Primaria | P11: si | Q11: si | R11: Armador, Patrón | S11: si | T11: Asociación de Armadores de Lanchas | U11: si | V11: Cortina costera | W11: bonito | X11: NA | Y11: NA | Z11: NA | AA11: NA | AB11: si | AC11: Mototaxi | AD11: 1 | AE11: 5 | AF11: si | AG11: Ama de casa | AH11: no | AI11: NA | AJ11: si | AK11: NA | AL11: si | AM11: NA | AN11: 1 | AO11: si | AP11: MAR DE LOS ANGELES | AQ11: CO-65907-BM | AR11: no | AS11: no | AT11: si | AU11: 13.73 | AV11: NA | AW11: NA | AX11: NA | AY11: NA | AZ11: NA | BA11: NA | BB11: 300-400 | BC11: Cortina superficial | BD11: 5 | BE11: 25-40 | BF11: Peruana | BG11: Tollo, Espada | BH11: si, caballa, tamborin | BI11: Enero-Diciembre | BJ11: 24-48 | BK11: malla 4.5 x 9250 m; con llevador (winche) | BL11: 17-18 | BM11: 3 | BN11: 15 | BO11: 300-500 | BP11: 8000-9000 | BQ11: Acopiador | BR11: 1.5 | BS11: Trampa Ovas | BT11: 2-4 | BU11: 25-40 | BV11: Peruana | BW11: Ova | BX11: no | BY11: Septiembre-Febrero | BZ11: 2 | CA11: Esteras y manta, con palmeras. Usa 18-20 trampas, en 3 filas de 6. Dimensiones de trampa 1.5x2 metros | CB11: 30-60 | CC11: 72 | CD11: 20-30 | CE11: 75-300 | CF11: 1000-5000 | CG11: Acopiador | CH11: 25-70 | CI11: Espinel | CJ11: Perico, Tollo | CK11: si, pota | CL11: Enero-Diciembre; Noviembre-Marzo | CM11: 12-24 | CN11: Linea madre: 12000 m. #anzuelos: 2500. 1 anzuelo/linea. Calibre: Tollo 2, Perico 5-6 | CO11: 8-10 | CP11: 2-3 | CQ11: 16 | CR11: 1000-3000 | CS11: 8000-9000 | CT11: Acopiador | CU11: 5 | CV11: Zona: Tollo (150-170 millas fuera de Ilo, La Planchada, Pisco); Ova (20 millas fuera de Ilo a Huacho); Perico (400 millas fuera de Pucusana). Sobre la ova, de Sep-Nov la trampa se deja 3 dias, y de Nov-Feb por 2 dias. Muy colaborador | CW11: 945 516 722 | CY11: Ova (20 millas fuera de Ilo a Huacho)
A12: KD-PUCUSANA-011 | B12: Kelly Diaz | C12: 45885 | D12: Juan De Dios Alvarez Garcia | E12: 07897247 | F12: 53 | G12: 45 | H12: Pucusana | I12: Pucusana | J12: Pucusana | K12: 21983 | L12: =DATEDIF(K12, DATE(2025,8,29), "Y") -> 65 | M12: M | N12: Viudo | O12: Superior Técnico | P12: si | Q12: si | R12: Tripulación | S12: si | T12: Asociación Gremio de Pescadores de Pucusana | U12: si | V12: Cortina costera | W12: pejerrey | X12: pinta | Y12: pota | Z12: NA | AA12: NA | AB12: si | AC12: Armador de embarcacion de costa | AD12: 0 | AE12: 2 | AF12: no | AG12: NA | AH12: si | AI12: 1 hijo: tripulante | AJ12: si | AK12: NA | AL12: si | AM12: NA | AN12: 2 (de costa ambas) | AO12: si | AP12: TITAN I | AQ12: CO-52539-BM | AR12: no | AS12: no | AT12: si | AU12: NS | AV12: TITAN II | AW12: CO-52540-BM | AX12: no | AY12: no | AZ12: si | BA12: NA | BB12: 450 | BC12: Cerco | BD12: 3 | BE12: 20-50 | BF12: Peruana | BG12: Bonito | BH12: no | BI12: Diciembre-Marzo | BJ12: 8 | BK12: con llevador (winche) | BL12: 7 | BM12: 1.5-3 | BN12: 10-14 | BO12: 200-250 | BP12: 2000 | BQ12: Acopiador | BR12: 1-5 | BS12: Cerco | BT12: 3 | BU12: 20-50 | BV12: Peruana | BW12: Tollo | BX12: no | BY12: Diciembre-Marzo | BZ12: 4-5 | CA12: con llevador (winche) | CB12: 15 | CC12: 10 | CD12: 12-15 | CE12: 300 | CF12: 6000-8000 | CG12: Acopiador | CH12: 2-7 | CI12: NA | CJ12: NA | CK12: NA | CL12: NA | CM12: NA | CN12: NA | CO12: NA | CP12: NA | CQ12: NA | CR12: NA | CS12: NA | CT12: NA | CU12: NA | CV12: Zona: Tollo (120-150 millas fuera de Pisco a Callao); Bonito (60-80 millas fuera de Pisco a Callao). | CW12: 923 593 622
A13: KD-PUCUSANA-012 | B13: Kelly Diaz | C13: 45885 | D13: Maria Antonieta Yzarnotegui Moreno | E13: 07386158 | F13: 25 | G13: 2 | H13: Pucusana | I13: Pucusana | J13: Pucusana | K13: 23900 | L13: =DATEDIF(K13, DATE(2025,8,29), "Y") -> 60 | M13: F | N13: Soltero | O13: Primaria | P13: si | Q13: Privado | R13: Tripulación | S13: no | T13: NA | U13: si | V13: Cortina costera | W13: pejerrey, bonito | X13: NA | Y13: NA | Z13: NA | AA13: NA | AB13: si | AC13: Decoración, Armador de embarcacion de costa | AD13: 0 | AE13: 2 | AF13: no | AG13: NA | AH13: si | AI13: 1 hijo: dueño | AJ13: si | AK13: NA | AL13: si | AM13: NA | AN13: 1 (de costa) | AO13: si | AP13: VICENZO | AQ13: CO-56337-BM | AR13: no | AS13: no | AT13: si | AU13: NA | AV13: NA | AW13: NA | AX13: NA | AY13: NA | AZ13: NA | BA13: NA | BB13: 340-360 | BC13: Cerco | BD13: 3-4 | BE13: 20-55 | BF13: Peruana | BG13: Bonito | BH13: no | BI13: Febrero-Mayo | BJ13: 7-9 | BK13: sin winche; superficial | BL13: 3-7 | BM13: 2-3 | BN13: 10-15 | BO13: 100-1000 | BP13: 400-4000 | BQ13: Acopiador | BR13: 1.5 | BS13: Trampa Ovas | BT13: 3-4 | BU13: 20-55 | BV13: Peruana | BW13: Ova | BX13: no | BY13: Septiembre-Febrero | BZ13: 4-5 | CA13: Esteras y manta, con zargazo. | CB13: 30 | CC13: 48-72 | CD13: 10-15 | CE13: 100 | CF13: 100-1000 | CG13: Acopiador | CH13: 16-45 | CI13: NA | CJ13: NA | CK13: NA | CL13: NA | CM13: NA | CN13: NA | CO13: NA | CP13: NA | CQ13: NA | CR13: NA | CS13: NA | CT13: NA | CU13: NA | CV13: Zona:Bonito (20-70 millas fuera de Marcona); Ova (150 millas fuera de Marcona). Una vez humedecida la trampa, ya no se puede volver a usar. Algunos peces voladores mueren despues de liberar sus gametos. La trampa se coloca al ras del agua, la embarcacion va al garete (a la deriva). Muy colaboradora | CW13: 945 489 966 | CY13: Ova (150 millas fuera de Marcona)
A14: KD-PUCUSANA-013 | B14: Kelly Diaz | C14: 45885 | D14: Erick Santacruz | E14: 48352437 | F14: 8 | G14: 8 | H14: Chilca | I14: Pucusana | J14: Pucusana | K14: 33891 | L14: =DATEDIF(K14, DATE(2025,8,29), "Y") -> 32 | M14: M | N14: Casado/Conviviente | O14: Secundaria | P14: si | Q14: si | R14: Tripulación | S14: no | T14: NA | U14: no | V14: NA | W14: NA | X14: NA | Y14: NA | Z14: NA | AA14: NA | AB14: si | AC14: Negocio | AD14: 3 | AE14: 2 | AF14: si | AG14: Ama de casa | AH14: no | AI14: NA | AJ14: no | AK14: La fuerza fisica natural no es la misma | AL14: si | AM14: NA | AN14: 0 | AO14: no | AP14: NA | AQ14: NA | AR14: NA | AS14: NA | AT14: NA | AU14: NA | AV14: NA | AW14: NA | AX14: NA | AY14: NA | AZ14: NA | BA14: NA | BB14: 300-400 | BC14: Pinta Potera | BD14: 3-4 | BE14: 16-55 | BF14: Peruana | BG14: Pota | BH14: no | BI14: Enero-Diciembre | BJ14: 24-36 | BK14: 2-3 viajes/mes | BL14: 4-11 | BM14: NS | BN14: NS | BO14: 1000-2000 | BP14: 15000-20000 | BQ14: Acopiador | BR14: 3 | BS14: NA | BT14: NA | BU14: NA | BV14: NA | BW14: NA | BX14: NA | BY14: NA | BZ14: NA | CA14: NA | CB14: NA | CC14: NA | CD14: NA | CE14: NA | CF14: NA | CG14: NA | CH14: NA | CI14: NA | CJ14: NA | CK14: NA | CL14: NA | CM14: NA | CN14: NA | CO14: NA | CP14: NA | CQ14: NA | CR14: NA | CS14: NA | CT14: NA | CU14: NA | CV14: Zona: Pota (30-200 millas fuera de Marcona a Pisco).
A15: KD-PUCUSANA-014 | B15: Kelly Diaz | C15: 45885 | D15: Jose Luis Sanchez Cardenas | E15: 07895056 | F15: 51 | G15: 36 | H15: Pucusana | I15: Pucusana | J15: Pucusana | K15: 23685 | L15: =DATEDIF(K15, DATE(2025,8,29), "Y") -> 60 | M15: M | N15: Casado/Conviviente | O15: Primaria | P15: si | Q15: si | R15: Patrón | S15: si | T15: Asociación Gremio de Pescadores de Pucusana | U15: si | V15: Cortina costera | W15: pejerrey | X15: NA | Y15: NA | Z15: NA | AA15: NA | AB15: no | AC15: NA | AD15: 5 | AE15: 2 | AF15: si | AG15: Negocio | AH15: no | AI15: NA | AJ15: si | AK15: NA | AL15: si | AM15: NA | AN15: 0 | AO15: no | AP15: NA | AQ15: NA | AR15: NA | AS15: NA | AT15: NA | AU15: NA | AV15: NA | AW15: NA | AX15: NA | AY15: NA | AZ15: NA | BA15: NA | BB15: 340-360 | BC15: Cortina superficial | BD15: 4-5 | BE15: 20-40 | BF15: Peruana | BG15: Bonito | BH15: no | BI15: Diciembre-Marzo | BJ15: 12 | BK15: #paños: 7, cocada: 4 pulgadas, malla 4.5 x 100 m | BL15: 7 | BM15: 2-3 | BN15: 12-18 | BO15: 1000 | BP15: 5000-6000 | BQ15: Acopiador | BR15: 1.5 | BS15: Cortina superficial | BT15: 4-5 | BU15: 20-40 | BV15: Peruana | BW15: Perico | BX15: no | BY15: Diciembre-Marzo | BZ15: 12 | CA15: #paños: 7, cocada: 5 pulgadas, malla 50 x 105 m | CB15: 7 | CC15: 2-3 | CD15: 10-12 | CE15: 1000 | CF15: 5000-6000 | CG15: Acopiador | CH15: 3.5-4 | CI15: Trampa Ovas | CJ15: Ova | CK15: no | CL15: Octubre-Marzo | CM15: 2 | CN15: Esteras y manta, con palmeras. Usa 15-16 trampas. Dimensiones de trampa 1.5x2.5 metros | CO15: 45-60 | CP15: 72 | CQ15: 15-20 | CR15: 150-300 | CS15: 1000-5000 | CT15: Acopiador | CU15: 40 | CV15: Zona: Bonito (20-60 millas fuera de Pucusana, Pisco); Perico (20-100 millas fuera de Pucusana, Pisco); Ova (100-120 millas fuera de Marcona). La estera cuando tiene huevos llama a mas peces. Llevan 30 esteras extras | CW15: 976 118 007 | CY15: Ova (100-120 millas fuera de Marcona)
A16: KD-PUCUSANA-015 | B16: Kelly Diaz | C16: 45885 | D16: Hilder Yangua Lloclla | E16: 42878933 | F16: 20 | G16: 20 | H16: Pucusana | I16: Pucusana | J16: Pucusana | K16: 30904 | L16: =DATEDIF(K16, DATE(2025,8,29), "Y") -> 41 | M16: M | N16: Casado/Conviviente | O16: Secundaria | P16: si | Q16: si | R16: Armador, Patrón | S16: no | T16: NA | U16: no | V16: NA | W16: NA | X16: NA | Y16: NA | Z16: NA | AA16: NA | AB16: no | AC16: NA | AD16: 3 | AE16: 2 | AF16: si | AG16: Ama de casa | AH16: no | AI16: NA | AJ16: si | AK16: NA | AL16: si | AM16: NA | AN16: 2 (solo 1 opera) | AO16: si | AP16: MILAGRO DE JESUS II | AQ16: IO-21998-BM | AR16: no | AS16: no | AT16: no | AU16: 21.4 | AV16: NA | AW16: NA | AX16: NA | AY16: NA | AZ16: NA | BA16: NA | BB16: 1000 | BC16: Espinel | BD16: 5 | BE16: 25-40 | BF16: Peruana | BG16: Tollo | BH16: si, caballa | BI16: Abril-Octubre | BJ16: 6 | BK16: Linea madre: 18 millas. #anzuelos: 1000. 1 anzuelo/linea. Calibre: 3 | BL16: 26 | BM16: 14 | BN16: 10-15 | BO16: 100-1000 | BP16: 4000-12000 | BQ16: Acopiador | BR16: 4 | BS16: NA | BT16: NA | BU16: NA | BV16: NA | BW16: NA | BX16: NA | BY16: NA | BZ16: NA | CA16: NA | CB16: NA | CC16: NA | CD16: NA | CE16: NA | CF16: NA | CG16: NA | CH16: NA | CI16: NA | CJ16: NA | CK16: NA | CL16: NA | CM16: NA | CN16: NA | CO16: NA | CP16: NA | CQ16: NA | CR16: NA | CS16: NA | CT16: NA | CU16: NA | CV16: Zona: Tollo azul (100-400 millas fuera de Marcona) | CW16: 982 088 280
A17: KD-PUCUSANA-016 | B17: Kelly Diaz | C17: 45887 | D17: Roberto Augusto Chumpitaz Flores | E17: 07897817 | F17: 47 | G17: 20 | H17: Pucusana | I17: Pucusana | J17: Pucusana | K17: 25848 | L17: =DATEDIF(K17, DATE(2025,8,29), "Y") -> 54 | M17: M | N17: Casado/Conviviente | O17: Secundaria | P17: si | Q17: si | R17: Armador, Patrón | S17: si | T17: Asociación Gremio de Pescadores de Pucusana | U17: si | V17: Cortina costera | W17: pejerrey | X17: NA | Y17: NA | Z17: NA | AA17: NA | AB17: no | AC17: NA | AD17: 1 | AE17: 3 | AF17: si | AG17: Promotora de educación | AH17: no | AI17: NA | AJ17: si | AK17: NA | AL17: si | AM17: NA | AN17: 1 | AO17: si | AP17: TORNADO | AQ17: CO-37583-BM | AR17: no | AS17: no | AT17: si | AU17: 5 | AV17: NA | AW17: NA | AX17: NA | AY17: NA | AZ17: NA | BA17: NA | BB17: 320-360 | BC17: Cortina superficial | BD17: 4 | BE17: 40-50 | BF17: Peruana | BG17: Tollo | BH17: no | BI17: Enero-Febrero | BJ17: 4 | BK17: #paños: 20, cocada: 6 pulgadas, malla 6 x 75 m | BL17: 10-15 | BM17: 10-12 | BN17: 10-12 | BO17: 300-500 | BP17: 1500 | BQ17: Acopiador | BR17: 1.2-2.5 | BS17: Espinel | BT17: 4 | BU17: 40-50 | BV17: Peruana | BW17: Perico | BX17: si, pota | BY17: Noviembre-Diciembre | BZ17: 4 | CA17: Linea madre: 1500 m. #anzuelos:1000. 1 anzuelo/linea. Calibre: 2 | CB17: 8-10 | CC17: 2-5 | CD17: 6-10 | CE17: 300-1000 | CF17: 3000-4000 | CG17: Acopiador | CH17: 7-8 | CI17: NA | CJ17: NA | CK17: NA | CL17: NA | CM17: NA | CN17: NA | CO17: NA | CP17: NA | CQ17: NA | CR17: NA | CS17: NA | CT17: NA | CU17: NA | CV17: Zona: Tollo (70-80 millas fuera de Pisco); Perico (100 millas fuera de Pucusana, Pisco, Ancon). Para el espinel, recorren la linea por completo revisando, y al segundo recorrido levantan toda la linea (total 10 horas) | CW17: 990 478 848
A18: KD-PUCUSANA-017 | B18: Kelly Diaz | C18: 45887 | D18: Marcos Eugenio Santisteban Sandoval | E18: 02737661 | F18: 20 | G18: 20 | H18: Pucusana | I18: Pucusana | J18: Pucusana | K18: 26290 | L18: =DATEDIF(K18, DATE(2025,8,29), "Y") -> 53 | M18: M | N18: Casado/Conviviente | O18: Secundaria | P18: si | Q18: no | R18: Armador | S18: si | T18: Asociación Gremio de Pescadores de Pucusana | U18: si | V18: Cortina costera | W18: pejerrey | X18: NA | Y18: NA | Z18: NA | AA18: NA | AB18: no | AC18: NA | AD18: 4 | AE18: 3 | AF18: si | AG18: Ama de casa | AH18: si | AI18: 1 hijo: tripulante | AJ18: no | AK18: Pesca de altura es peligrosa, vientos fuertes | AL18: si | AM18: NA | AN18: 1 | AO18: si | AP18: JIRETH I | AQ18: PS-26309-BM | AR18: no | AS18: si | AT18: si | AU18: 8 | AV18: JIRETH I | AW18: NA | AX18: NA | AY18: NA | AZ18: NA | BA18: NA | BB18: 250-300 | BC18: Cortina superficial | BD18: 4-5 | BE18: 20-40 | BF18: Peruana | BG18: Bonito | BH18: no | BI18: Diciembre-Junio | BJ18: 12-14 | BK18: #paños: 6-7, cocada: 4 pulgadas, malla 9 x 105 m | BL18: 7 | BM18: 2-4 | BN18: 4-5 | BO18: 500-1000 | BP18: 2000-5000 | BQ18: Acopiador | BR18: 2 | BS18: Pinta Potera | BT18: 4-5 | BU18: 20-40 | BV18: Peruana | BW18: Pota | BX18: no | BY18: Mayo-Julio | BZ18: 6-9 | CA18: 2-3 viajes/mes | CB18: 7 | CC18: NS | CD18: NS | CE18: 1000-2000 | CF18: 6000-7000 | CG18: Acopiador | CH18: 2.2 | CI18: NA | CJ18: NA | CK18: NA | CL18: NA | CM18: NA | CN18: NA | CO18: NA | CP18: NA | CQ18: NA | CR18: NA | CS18: NA | CT18: NA | CU18: NA | CV18: Zona: Bonito (70-80 millas fuera de Callao a Pisco); Pota (70-80 millas fuera de Callao, Pucusana, Pisco). | CW18: 933 957 502
A19: KD-PUCUSANA-018 | B19: Kelly Diaz | C19: 45887 | D19: Carlos Alexander Florian Peña | E19: 40515591 | F19: 27 | G19: 20 | H19: Pucusana | I19: Pucusana | J19: Pucusana, Callao, etc | K19: 29288 | L19: =DATEDIF(K19, DATE(2025,8,29), "Y") -> 45 | M19: M | N19: Casado/Conviviente | O19: Superior Técnico | P19: si | Q19: Privado | R19: Patrón | S19: si | T19: Asociación Gremio de Pescadores de Pucusana | U19: si | V19: Cortina costera | W19: pejerrey, chauchilla | X19: NA | Y19: NA | Z19: NA | AA19: NA | AB19: no | AC19: NA | AD19: 3 | AE19: 2 | AF19: si | AG19: Cocinera | AH19: no | AI19: NA | AJ19: si | AK19: NA | AL19: si | AM19: NA | AN19: 0 | AO19: no | AP19: NA | AQ19: NA | AR19: NA | AS19: NA | AT19: NA | AU19: NA | AV19: NA | AW19: NA | AX19: NA | AY19: NA | AZ19: NA | BA19: NA | BB19: 180 | BC19: Espinel | BD19: 4 | BE19: 25-30 | BF19: Peruana | BG19: Perico | BH19: si, pota, barrilete | BI19: Diciembre-Enero | BJ19: 5-7 | BK19: Linea madre: 8000 metros. #anzuelos: 1000. 1 anzuelo/linea. Calibre: 3 | BL19: 6 | BM19: 2-5 | BN19: 4-5 | BO19: 200-400 | BP19: 2000 | BQ19: Acopiador | BR19: 5-10 | BS19: Trampa Ovas | BT19: 4 | BU19: 25-30 | BV19: Peruana | BW19: Ova | BX19: no | BY19: Septiembre-Noviembre | BZ19: 2 | CA19: Esteras y manta, con palmeras. Usa 3 trampas. | CB19: 30 | CC19: 48-72 | CD19: 10-15 | CE19: 100-200 | CF19: 1000-1500 | CG19: Acopiador | CH19: 32 | CI19: NA | CJ19: NA | CK19: NA | CL19: NA | CM19: NA | CN19: NA | CO19: NA | CP19: NA | CQ19: NA | CR19: NA | CS19: NA | CT19: NA | CU19: NA | CV19: Zona: Perico (80-100 millas fuera de Pucusana); Ovas (100 millas fuera de Marcona). Las trampas se colocan, en orden de abajo hacia arriba: palmera, estera, manta. | CW19: 961 285 950 | CY19: Ovas (100 millas fuera de Marcona)
A20: KD-PUCUSANA-019 | B20: Kelly Diaz | C20: 45887 | D20: Frank Ericson Bravo Tapia | E20: 42154834 | F20: 15 | G20: 15 | H20: Pucusana | I20: Pucusana | J20: Pucusana | K20: 30314 | L20: =DATEDIF(K20, DATE(2025,8,29), "Y") -> 42 | M20: M | N20: Divorciado | O20: Secundaria | P20: si | Q20: si | R20: Tripulación | S20: si | T20: Asociación Gremio de Pescadores de Pucusana | U20: no | V20: NA | W20: NA | X20: NA | Y20: NA | Z20: NA | AA20: NA | AB20: si | AC20: Turismo | AD20: 0 | AE20: 2 | AF20: no | AG20: NA | AH20: no | AI20: NA | AJ20: si | AK20: NA | AL20: si | AM20: NA | AN20: 0 | AO20: no | AP20: NA | AQ20: NA | AR20: NA | AS20: NA | AT20: NA | AU20: NA | AV20: NA | AW20: NA | AX20: NA | AY20: NA | AZ20: NA | BA20: NA | BB20: 140-160 | BC20: Cortina superficial | BD20: 3 | BE20: 30-40 | BF20: Peruana | BG20: Bonito | BH20: no | BI20: Junio-Julio | BJ20: 6-8 | BK20: #paños: 10, cocada: 3.5-4 pulgadas | BL20: 3-4 | BM20: 1-2 | BN20: 12-18 | BO20: 200-1000 | BP20: 800-1400 | BQ20: Acopiador | BR20: no recuerda | BS20: Espinel | BT20: 3 | BU20: 30-40 | BV20: Peruana | BW20: Perico | BX20: si | BY20: Diciembre-Febrero | BZ20: 6-8 | CA20: #anzuelos:1200. 1 anzuelo/linea. Calibre: 3 | CB20: 10-11 | CC20: 2-5 | CD20: 10 | CE20: 800-1000 | CF20: 3000-5000 | CG20: Acopiador | CH20: NS | CI20: NA | CJ20: NA | CK20: NA | CL20: NA | CM20: NA | CN20: NA | CO20: NA | CP20: NA | CQ20: NA | CR20: NA | CS20: NA | CT20: NA | CU20: NA | CV20: Zona: Bonito (50 millas fuera de Pucusana); Perico (80-120 millas fuera de Marcona, Ilo). | CW20: 933 040 270
A21: KD-PUCUSANA-020 | B21: Kelly Diaz | C21: 45887 | D21: William Junior Machare Farfan | E21: 46412591 | F21: 12 | G21: 12 | H21: Pucusana | I21: Pucusana | J21: Pucusana, Atico, La Planchada | K21: 32740 | L21: =DATEDIF(K21, DATE(2025,8,29), "Y") -> 36 | M21: M | N21: Soltero | O21: Primaria | P21: si | Q21: No tiene | R21: Patrón | S21: no | T21: NA | U21: no | V21: NA | W21: NA | X21: NA | Y21: NA | Z21: NA | AA21: NA | AB21: no | AC21: NA | AD21: 5 | AE21: 3 | AF21: si | AG21: Profesional Independiente | AH21: no | AI21: NA | AJ21: si | AK21: NA | AL21: si | AM21: NA | AN21: 1 | AO21: no | AP21: MIKELA | AQ21: CO-20058-BM | AR21: no | AS21: no | AT21: si | AU21: 10 | AV21: NA | AW21: NA | AX21: NA | AY21: NA | AZ21: NA | BA21: NA | BB21: 250-280 | BC21: Trampa Ovas | BD21: 3-5 | BE21: 28-41 | BF21: Peruana | BG21: Ova | BH21: no | BI21: Septiembre-Marzo | BJ21: 7 | BK21: Esteras y manta, con palmeras o manguera. Usa 18 trampas, en 3 filas de 6. Dimensiones de trampa 3.2x3 metros | BL21: 30-40 | BM21: 72 | BN21: 10-12 | BO21: 120-150 | BP21: 800-2000 | BQ21: Acopiador | BR21: 35 | BS21: NA | BT21: NA | BU21: NA | BV21: NA | BW21: NA | BX21: NA | BY21: NA | BZ21: NA | CA21: NA | CB21: NA | CC21: NA | CD21: NA | CE21: NA | CF21: NA | CG21: NA | CH21: NA | CI21: NA | CJ21: NA | CK21: NA | CL21: NA | CM21: NA | CN21: NA | CO21: NA | CP21: NA | CQ21: NA | CR21: NA | CS21: NA | CT21: NA | CU21: NA | CV21: Zona: Ova (70-80 millas fuera de Atico, La Planchada). Ova con ojo no se vende. | CW21: 907 458 484 | CY21: Ova (70-80 millas fuera de Atico, La Planchada)
A22: KD-PUCUSANA-021 | B22: Kelly Diaz | C22: 45887 | D22: Genaro Angulo Guerra | E22: 07897867 | F22: 43 | G22: 41 | H22: Pucusana | I22: Pucusana | J22: Pucusana, Pisco | K22: 25679 | L22: =DATEDIF(K22, DATE(2025,8,29), "Y") -> 55 | M22: M | N22: Soltero | O22: Primaria | P22: si | Q22: si | R22: Armador, Patrón | S22: si | T22: Asociación Gremio de Pescadores de Pucusana | U22: si | V22: Pinta | W22: jurel, caballa, lorna, chauchilla | X22: Cortina costera | Y22: jurel, caballa, lorna, chauchilla | Z22: Cerco costero | AA22: jurel, caballa, lorna, chauchilla | AB22: no | AC22: NA | AD22: 1 | AE22: 3 | AF22: si | AG22: Compra y venta de pesca | AH22: si | AI22: 1 hijo: patrón y dueño | AJ22: si | AK22: NA | AL22: si | AM22: NA | AN22: 3 (solo 1 opera) | AO22: si | AP22: MI SEBASTIAN | AQ22: CO-41020-BM | AR22: no | AS22: no | AT22: si | AU22: 8 | AV22: NA | AW22: NA | AX22: NA | AY22: NA | AZ22: NA | BA22: NA | BB22: 180-360 | BC22: Cortina superficial | BD22: 8 | BE22: 25-50 | BF22: Peruana | BG22: Bonito | BH22: no | BI22: Octubre-Marzo | BJ22: 45-65 | BK22: #paños: 10, cocada: 4 pulgadas, malla 4.5 x 120 m | BL22: 2-7 | BM22: 1-2 | BN22: 6-30 | BO22: 200-2000 | BP22: 2000 | BQ22: Acopiador | BR22: 4-5 | BS22: Cortina superficial | BT22: 4 | BU22: 25-50 | BV22: Peruana | BW22: Perico | BX22: no | BY22: Octubre-Marzo | BZ22: 6 | CA22: #paños: 20, cocada: 6 pulgadas, malla 4.5 x 120 m | CB22: 15-30 | CC22: 3-4 | CD22: 30-40 | CE22: 200-2000 | CF22: 20000 | CG22: Acopiador | CH22: 9-18 | CI22: NA | CJ22: NA | CK22: NA | CL22: NA | CM22: NA | CN22: NA | CO22: NA | CP22: NA | CQ22: NA | CR22: NA | CS22: NA | CT22: NA | CU22: NA | CV22: Zona: Bonito (10-100 millas fuera de Chimbote a Callao); Perico (100-180 millas fuera de Ancon, Pisco). | CW22: 937 139 760
A23: KD-PUCUSANA-022 | B23: Kelly Diaz | C23: 45887 | D23: Pedro Miguel Baldiño Pisconte | E23: 44354186 | F23: 20 | G23: 20 | H23: Pucusana | I23: Pucusana | J23: Pucusana, Pisco, Callao | K23: 31592 | L23: =DATEDIF(K23, DATE(2025,8,29), "Y") -> 39 | M23: M | N23: Casado/Conviviente | O23: Secundaria | P23: si | Q23: si | R23: Armador | S23: si | T23: Asociación Gremio de Pescadores de Pucusana | U23: si | V23: Pinta | W23: pota, bonito, jurel | X23: NA | Y23: NA | Z23: NA | AA23: NA | AB23: no | AC23: NA | AD23: 5 | AE23: 2 | AF23: si | AG23: Ama de casa | AH23: no | AI23: NA | AJ23: si | AK23: NA | AL23: si | AM23: NA | AN23: 1 | AO23: si | AP23: JESUS RIVALDO | AQ23: CO-35916-BM | AR23: no | AS23: no | AT23: si | AU23: 4.5 | AV23: NA | AW23: NA | AX23: NA | AY23: NA | AZ23: NA | BA23: NA | BB23: 120 | BC23: Cortina superficial | BD23: 4 | BE23: 20-60 | BF23: Peruana | BG23: Bonito | BH23: no | BI23: Octubre-Febrero | BJ23: 10-15 | BK23: #paños: 8, cocada: 4 pulgadas, malla 4.5 x 4.5 m | BL23: 3-7 | BM23: 2-3 | BN23: 6-12 | BO23: 1000-4000 | BP23: 4000 | BQ23: Acopiador | BR23: 1-5 | BS23: Pinta Potera | BT23: 4 | BU23: 20-60 | BV23: Peruana | BW23: Pota | BX23: no | BY23: Enero-Diciembre | BZ23: 48 | CA23: 4 viajes/mes | CB23: 3-7 | CC23: NS | CD23: NS | CE23: 1000-2000 | CF23: 4000 | CG23: Acopiador | CH23: 1-13 | CI23: NA | CJ23: NA | CK23: NA | CL23: NA | CM23: NA | CN23: NA | CO23: NA | CP23: NA | CQ23: NA | CR23: NA | CS23: NA | CT23: NA | CU23: NA | CV23: Zona: Bonito (40-50 millas fuera de Pisco); Pota (40-50 millas fuera de Pisco). Comenta molestia en que los pescadores solo conocen el precio del comprador de pota, pero no conocen el precio de la empresa | CW23: 936 219 115
A24: KD-PUCUSANA-023 | B24: Kelly Diaz | C24: 45887 | D24: Luis Benito Castillo Yataco | E24: 07895444 | F24: 51 | G24: 35 | H24: Pucusana | I24: Pucusana | J24: Pucusana, Pisco, Callao, Atico, La Planchada | K24: 18486 | L24: =DATEDIF(K24, DATE(2025,8,29), "Y") -> 75 | M24: M | N24: Casado/Conviviente | O24: Primaria | P24: si | Q24: si | R24: Armador | S24: si | T24: Asociación Gremio de Pescadores de Pucusana | U24: no | V24: NA | W24: NA | X24: NA | Y24: NA | Z24: NA | AA24: NA | AB24: no | AC24: NA | AD24: 1 | AE24: 2 | AF24: si | AG24: Negocio | AH24: no | AI24: NA | AJ24: si | AK24: NA | AL24: si | AM24: NA | AN24: 1 | AO24: si | AP24: KELLY II | AQ24: CO-22405-BM | AR24: no | AS24: no | AT24: si | AU24: 10 | AV24: NA | AW24: NA | AX24: NA | AY24: NA | AZ24: NA | BA24: NA | BB24: 200-300 | BC24: Pinta Potera | BD24: 4 | BE24: 20-30 | BF24: Peruana | BG24: Pota | BH24: no | BI24: Enero-Diciembre | BJ24: 24 | BK24: 2 viajes/mes | BL24: 8-15 | BM24: NS | BN24: NS | BO24: 2000-3000 | BP24: 10000-15000 | BQ24: Acopiador | BR24: 1.5-3 | BS24: NA | BT24: NA | BU24: NA | BV24: NA | BW24: NA | BX24: NA | BY24: NA | BZ24: NA | CA24: NA | CB24: NA | CC24: NA | CD24: NA | CE24: NA | CF24: NA | CG24: NA | CH24: NA | CI24: NA | CJ24: NA | CK24: NA | CL24: NA | CM24: NA | CN24: NA | CO24: NA | CP24: NA | CQ24: NA | CR24: NA | CS24: NA | CT24: NA | CU24: NA | CV24: Zona: Pota (40-80 millas fuera de Pisco e Ilo). Suelen pescar la pota 6 a 8 hr en la noche | CW24: 931 998 662
A25: KD-PUCUSANA-024 | B25: Kelly Diaz | C25: 45887 | D25: Jose Carlos Carrera Astete | E25: 04641260 | F25: 30 | G25: 20 | H25: Pucusana | I25: Pucusana | J25: Pucusana | K25: 25713 | L25: =DATEDIF(K25, DATE(2025,8,29), "Y") -> 55 | M25: M | N25: Casado/Conviviente | O25: Superior Técnico | P25: si | Q25: si | R25: Armador, Patrón | S25: si | T25: Asociación de Pescadores Armaderos de Pucusana | U25: no | V25: NA | W25: NA | X25: NA | Y25: NA | Z25: NA | AA25: NA | AB25: no | AC25: NA | AD25: 1 | AE25: 3 | AF25: si | AG25: Ama de casa | AH25: no | AI25: NA | AJ25: no | AK25: La fuerza fisica natural no es la misma | AL25: no | AM25: tendria dificultad en rendir fisicamente como un hombre | AN25: 1 | AO25: si | AP25: MICHAEL JORDAN 3 | AQ25: MO-57592-BM | AR25: si | AS25: si | AT25: si | AU25: 12 | AV25: NA | AW25: NA | AX25: NA | AY25: NA | AZ25: NA | BA25: NA | BB25: 1200-1500 | BC25: Pinta Potera | BD25: 6 | BE25: 25-40 | BF25: Peruana | BG25: Pota | BH25: no | BI25: Enero-Diciembre | BJ25: 12-48 | BK25: 1-4 viajes/mes | BL25: 4-22 | BM25: NS | BN25: NS | BO25: NS | BP25: 12000-20000 | BQ25: Acopiador | BR25: 2.3 | BS25: Espinel | BT25: 6 | BU25: 25-40 | BV25: Peruana | BW25: Perico | BX25: si | BY25: Octubre-Febrero | BZ25: 5-6 | CA25: Linea madre: 26000 m. #anzuelos:2200. 1 anzuelo/linea. Calibre: 5 | CB25: 20 | CC25: 3-4 | CD25: 15-20 | CE25: 100-1500 | CF25: 8000-1000 | CG25: Acopiador | CH25: 6 | CI25: Espinel | CJ25: Tollo | CK25: si, caballa | CL25: Octubre-Febrero | CM25: 4 | CN25: Linea madre: 26000 m. #anzuelos:2200. 1 anzuelo/linea. Calibre: 5 | CO25: 25-30 | CP25: 10-12 | CQ25: 12-15 | CR25: 80-300 | CS25: 4000-5000 | CT25: Acopiador | CU25: 3.3-3.5 | CV25: Zona: Pota (200 millas fuera de Tumbes a Tacna); Perico (200-250 millas fuera de Ilo a Piura); Tollo (150-200 millas fuera de Ilo a Piura). | CW25: 999 001 359
A26: KD-PUCUSANA-025 | B26: Kelly Diaz | C26: 45888 | D26: Ignacio Luis Alfredo Noa Chambi | E26: 80265947 | F26: 34 | G26: 29 | H26: Mollendo | I26: Pucusana | J26: Pucusana | K26: 28004 | L26: =DATEDIF(K26, DATE(2025,8,29), "Y") -> 48 | M26: M | N26: Soltero | O26: Primaria | P26: si | Q26: No tiene | R26: Patrón | S26: no | T26: NA | U26: si | V26: Cortina costera | W26: pejerrey | X26: NA | Y26: NA | Z26: NA | AA26: NA | AB26: no | AC26: NA | AD26: 3 | AE26: 2 | AF26: no | AG26: NA | AH26: no | AI26: NA | AJ26: no | AK26: La fuerza fisica natural no es la misma; en huevera si es mas posible | AL26: si | AM26: NA | AN26: 1 | AO26: no | AP26: RODRIGO Y ALVARO | AQ26: PS-57411-BM | AR26: no | AS26: no | AT26: si | AU26: 4 | AV26: NA | AW26: NA | AX26: NA | AY26: NA | AZ26: NA | BA26: NA | BB26: 140-200 | BC26: Pinta Potera | BD26: 4 | BE26: 17-55 | BF26: Peruana y Extranjera | BG26: Pota | BH26: no | BI26: Enero-Diciembre | BJ26: 48 | BK26: 4 viajes/mes | BL26: 7 | BM26: NS | BN26: NS | BO26: 500-1000 | BP26: 1000-7000 | BQ26: Acopiador | BR26: 1.5-6 | BS26: NA | BT26: NA | BU26: NA | BV26: NA | BW26: NA | BX26: NA | BY26: NA | BZ26: NA | CA26: NA | CB26: NA | CC26: NA | CD26: NA | CE26: NA | CF26: NA | CG26: NA | CH26: NA | CI26: NA | CJ26: NA | CK26: NA | CL26: NA | CM26: NA | CN26: NA | CO26: NA | CP26: NA | CQ26: NA | CR26: NA | CS26: NA | CT26: NA | CU26: NA | CV26: Zona: Pota (30-200 millas fuera de Pucusana). | CW26: 967 898 473 | CX26: NC
A27: KD-PUCUSANA-026 | B27: Kelly Diaz | C27: 45888 | D27: Wilson Requejo Cueva | E27: 46955312 | F27: 18 | G27: 18 | H27: Pucusana | I27: Pucusana | J27: Pucusana | K27: 33507 | L27: =DATEDIF(K27, DATE(2025,8,29), "Y") -> 33 | M27: M | N27: Soltero | O27: Secundaria | P27: si | Q27: si | R27: Patrón | S27: no | T27: NA | U27: no | V27: NA | W27: NA | X27: NA | Y27: NA | Z27: NA | AA27: NA | AB27: no | AC27: NA | AD27: 3 | AE27: 3 | AF27: no | AG27: NA | AH27: no | AI27: NA | AJ27: si | AK27: NA | AL27: si | AM27: NA | AN27: 0 | AO27: no | AP27: MICHAELL JORDAN 1 | AQ27: MO-60112-BM | AR27: no | AS27: no | AT27: si | AU27: NS | AV27: NA | AW27: NA | AX27: NA | AY27: NA | AZ27: NA | BA27: NA | BB27: 1000 | BC27: Espinel | BD27: 4 | BE27: 22-30 | BF27: Peruana | BG27: Tollo | BH27: si | BI27: Junio-Julio | BJ27: 2-3 | BK27: Linea madre: 29600 metros. #anzuelos: 900. 1 anzuelo/linea. Calibre: 3 | BL27: 18-25 | BM27: 5-6 | BN27: 12-15 | BO27: 600-700 | BP27: 8000-10000 | BQ27: Acopiador | BR27: 6 | BS27: Espinel | BT27: 6 | BU27: 22-30 | BV27: Peruana | BW27: Perico | BX27: si | BY27: Octubre-Marzo | BZ27: 6-7 | CA27: Linea madre: 29600 metros. #anzuelos: 900. 1 anzuelo/linea. Calibre: 5 | CB27: 15-18 | CC27: 1-2 | CD27: 30 | CE27: 600-700 | CF27: 8000-10000 | CG27: Acopiador | CH27: 8-15 | CI27: NA | CJ27: NA | CK27: NA | CL27: NA | CM27: NA | CN27: NA | CO27: NA | CP27: NA | CQ27: NA | CR27: NA | CS27: NA | CT27: NA | CU27: NA | CV27: Zona: Tollo (400 millas fuera de Ilo); Perico (500-600 millas fuera de Pucusana). | CW27: 953 084 203
A28: KD-PUCUSANA-027 | B28: Kelly Diaz | C28: 45888 | D28: Carlos Ancajima Martinez | E28: 80430112 | F28: 35 | G28: 35 | H28: Pucusana | I28: Pucusana | J28: Pucusana | K28: 27646 | L28: =DATEDIF(K28, DATE(2025,8,29), "Y") -> 49 | M28: M | N28: Casado/Conviviente | O28: Secundaria | P28: si | Q28: si | R28: Patrón | S28: si | T28: Asociación Gremio de Pescadores de Pucusana | U28: si | V28: Cortina costera | W28: pejerrey, cachema, lorna | X28: NA | Y28: NA | Z28: NA | AA28: NA | AB28: no | AC28: NA | AD28: 3 | AE28: 2 | AF28: si | AG28: Limpia pejerrey | AH28: no | AI28: NA | AJ28: si | AK28: NA | AL28: si | AM28: NA | AN28: 1 | AO28: no | AP28: RUTH | AQ28: NS | AR28: no | AS28: no | AT28: si | AU28: 8 | AV28: NA | AW28: NA | AX28: NA | AY28: NA | AZ28: NA | BA28: NA | BB28: 350 | BC28: Espinel | BD28: 6 | BE28: 20-50 | BF28: Peruana | BG28: Perico | BH28: si | BI28: Septiembre-Noviembre | BJ28: 5-6 | BK28: Linea madre: 18500 metros. #anzuelos: 2000. 1 anzuelo/linea. Calibre: 5 | BL28: 30 | BM28: 3-4 | BN28: 6 | BO28: 700-1000 | BP28: 4000-5000 | BQ28: Acopiador | BR28: 8-9 | BS28: Trampa Ovas | BT28: 4 | BU28: 20-50 | BV28: Peruana | BW28: Ova | BX28: no | BY28: Octubre-Diciembre | BZ28: 1-2 | CA28: Esteras y manta, con palmeras. Usa 40 trampas, en 4 filas de 10. Dimensiones de trampa 2.5x1.5 metros | CB28: 30 | CC28: 72 | CD28: 10 | CE28: 50-100 | CF28: 800-1000 | CG28: Acopiador | CH28: 40 | CI28: NA | CJ28: NA | CK28: NA | CL28: NA | CM28: NA | CN28: NA | CO28: NA | CP28: NA | CQ28: NA | CR28: NA | CS28: NA | CT28: NA | CU28: NA | CV28: Zona: Perico (250 millas fuera de Huacho y Mataran); Ova (250 millas fuera de Huacho hacia el sur). Tira sus trampas de 10 en 10. Ova con ojo no se vende. | CY28: Ova (250 millas fuera de Huacho hacia el sur)
A29: KD-PUCUSANA-028 | B29: Kelly Diaz | C29: 45888 | D29: Olger Jeefer Panta Silupu | E29: 47808459 | F29: 10 | G29: 10 | H29: Pucusana | I29: Pucusana | J29: Pucusana, Ilo, Callao, Salaverry | K29: 33165 | L29: =DATEDIF(K29, DATE(2025,8,29), "Y") -> 34 | M29: M | N29: Soltero | O29: Secundaria | P29: si | Q29: Privado | R29: Patrón | S29: no | T29: NA | U29: no | V29: NA | W29: NA | X29: NA | Y29: NA | Z29: NA | AA29: NA | AB29: si | AC29: Turismo | AD29: 0 | AE29: 0 | AF29: no | AG29: NA | AH29: no | AI29: NA | AJ29: no | AK29: La fuerza fisica natural no es la misma; la habilidad es la misma | AL29: si | AM29: NA | AN29: 1 | AO29: no | AQ29: IO-29620-BM | AR29: no | AS29: no | AT29: si | AU29: 10 | AV29: NA | AW29: NA | AX29: NA | AY29: NA | AZ29: NA | BA29: NA | BB29: 400-800 | BC29: Espinel | BD29: 5-6 | BE29: 20-50 | BF29: Peruana | BG29: Tollo | BH29: si | BI29: Enero-Diciembre | BJ29: 12-20 | BK29: Linea madre: 13500 metros. #anzuelos: 2000. 1 anzuelo/linea. Calibre: 4 | BL29: 15-30 | BM29: 3-5 | BN29: 20-50 | BO29: 300-4000 | BP29: 5000-12000 | BQ29: Acopiador | BR29: 5 | BS29: Espinel | BT29: 5-6 | BU29: 20-50 | BV29: Peruana | BW29: Perico | BX29: si | BY29: Octubre-Marzo | BZ29: 6-10 | CA29: Linea madre: 22500 metros. #anzuelos: 2500. 1 anzuelo/linea. Calibre: 5 | CB29: 15-20 | CC29: 3-4 | CD29: 40-60 | CE29: 200-1000 | CF29: 5000-14000 | CG29: Acopiador | CH29: 6-20 | CI29: NA | CJ29: NA | CK29: NA | CL29: NA | CM29: NA | CN29: NA | CO29: NA | CP29: NA | CQ29: NA | CR29: NA | CS29: NA | CT29: NA | CU29: NA | CV29: Zona: Perico (90-200 millas fuera de Pucusana hasta Chile); Tollo (500 millas fuera de Pucusana hasta Chile). El espinel del tollo usa un alambre en vez de linea, para sujetar el anzuelo. | CW29: 932 329 924
A30: KD-PUCUSANA-029 | B30: Kelly Diaz | C30: 45888 | D30: Luis Alberto Avila Bravo | E30: 80091938 | F30: 44 | G30: 37 | H30: Pucusana | I30: Pucusana | J30: Pucusana, Marcona, Callao, Ancón | K30: 26752 | L30: =DATEDIF(K30, DATE(2025,8,29), "Y") -> 52 | M30: M | N30: Divorciado | O30: Secundaria | P30: si | Q30: si | R30: Tripulación | S30: si | T30: Asociación Gremio de Pescadores de Pucusana | U30: si | V30: Cortina costera | W30: pejerrey, lorna | X30: NA | Y30: NA | Z30: NA | AA30: NA | AB30: no | AC30: NA | AD30: 0 | AE30: 2 | AF30: no | AG30: NA | AH30: si | AI30: 1 hijo: tripulante | AJ30: si | AK30: NA | AL30: si | AM30: NA | AN30: 0 | AO30: no | AP30: NA | AQ30: NA | AR30: NA | AS30: NA | AT30: NA | AU30: NA | AV30: NA | AW30: NA | AX30: NA | AY30: NA | AZ30: NA | BA30: NA | BB30: 50-100 | BC30: Cortina superficial | BD30: 3 | BE30: 25-55 | BF30: Peruana | BG30: Bonito | BH30: no | BI30: Octubre-Febrero | BJ30: 25-35 | BK30: #paños: 16, cocada: 4 pulgadas, malla 4.5 x 90 m | BL30: 1-7 | BM30: 2-3 | BN30: 2-8 | BO30: 40-500 | BP30: 4000-5000 | BQ30: Acopiador | BR30: 1.2-4 | BS30: Pinta Potera | BT30: 3-4 | BU30: 25-55 | BV30: Peruana | BW30: Pota | BX30: no | BY30: Junio-Agosto | BZ30: 6-12 | CA30: 2-4 viajes/mes | CB30: 4-15 | CC30: NS | CD30: NS | CE30: NS | CF30: 4000-10000 | CG30: Acopiador | CH30: 1-20 | CI30: NA | CJ30: NA | CK30: NA | CL30: NA | CM30: NA | CN30: NA | CO30: NA | CP30: NA | CQ30: NA | CR30: NA | CS30: NA | CT30: NA | CU30: NA | CV30: Zona: Bonito (50-170 millas fuera de Marcona); Pota (50-100 millas fuera de Marcona).
A31: KD-PUCUSANA-030 | B31: Kelly Diaz | C31: 45888 | D31: Oswer Ivan Dominguez Rondoy | E31: 46376229 | F31: 10 | G31: 4 | H31: Pucusana | I31: Pucusana | J31: Pucusana, Callao | K31: 32957 | L31: =DATEDIF(K31, DATE(2025,8,29), "Y") -> 35 | M31: M | N31: Casado/Conviviente | O31: Secundaria | P31: si | Q31: si | R31: Patrón | S31: no | T31: NA | U31: no | V31: NA | W31: NA | X31: NA | Y31: NA | Z31: NA | AA31: NA | AB31: si | AC31: Negocio | AD31: 4 | AE31: 1 | AF31: si | AG31: Profesional Independiente | AH31: no | AI31: NA | AJ31: no | AK31: La fuerza fisica natural no es la misma | AL31: si | AM31: NA | AN31: 0 | AO31: no | AQ31: CO-45544-CM | AR31: si | AS31: no | AT31: si | AU31: 10 | AV31: NA | AW31: NA | AX31: NA | AY31: NA | AZ31: NA | BA31: NA | BB31: 1200-1400 | BC31: Espinel | BD31: 8 | BE31: 20-55 | BF31: Peruana | BG31: Perico | BH31: si | BI31: Noviembre-Abril | BJ31: 6 | BK31: Linea madre: 15000 metros. #anzuelos: 2500. 1 anzuelo/linea. Calibre: 5 | BL31: 20-30 | BM31: 2-3 | BN31: 9-15 | BO31: 500-2000 | BP31: 4000-20000 | BQ31: Acopiador | BR31: 6-12 | BS31: Pinta Potera | BT31: 5-6 | BU31: 20-55 | BV31: Peruana | BW31: Pota | BX31: no | BY31: Enero-Diciembre | BZ31: 24-48 | CA31: 2-4 viajes/mes | CB31: 8-15 | CC31: NS | CD31: NS | CE31: 500-1500 | CF31: 10000-25000 | CG31: Acopiador | CH31: 1.2-3 | CI31: NA | CJ31: NA | CK31: NA | CL31: NA | CM31: NA | CN31: NA | CO31: NA | CP31: NA | CQ31: NA | CR31: NA | CS31: NA | CT31: NA | CU31: NA | CV31: Zona: Perico (700-200 millas fuera de Paita a Ilo); Pota (80-250 millas fuera de Pucusana a Ilo). | CW31: 954 191 597
A32: KD-PUCUSANA-031 | B32: Kelly Diaz | C32: 45888 | D32: Augusto Rodolfo Llanos Luyo | E32: 09526224 | F32: 36 | G32: 31 | H32: Pucusana | I32: Pucusana | J32: Pucusana, Marcona, Callao, Atico, Salaverry | K32: 25527 | L32: =DATEDIF(K32, DATE(2025,8,29), "Y") -> 55 | M32: M | N32: Soltero | O32: Secundaria | P32: si | Q32: No tiene | R32: Patrón | S32: no | T32: NA | U32: no | V32: NA | W32: NA | X32: NA | Y32: NA | Z32: NA | AA32: NA | AB32: no | AC32: NA | AD32: 4 | AE32: 4 | AF32: no | AG32: NA | AH32: no | AI32: NA | AJ32: no | AK32: La fuerza fisica natural no es la misma | AL32: no | AM32: tendria dificultad en rendir fisicamente como un hombre | AN32: 0 | AO32: no | AP32: CARLOS JOEL | AQ32: NS | AR32: no | AS32: no | AT32: si | AU32: 7 | AV32: NA | AW32: NA | AX32: NA | AY32: NA | AZ32: NA | BA32: NA | BB32: 80 | BC32: Cortina superficial | BD32: 4 | BE32: 30-50 | BF32: Peruana y Extranjera | BG32: Perico | BH32: no | BI32: Noviembre-Diciembre | BJ32: 4-5 | BK32: #paños: 10, cocada: 4 pulgadas, malla 6.75 x 4.5 m | BL32: 8-10 | BM32: 2-3 | BN32: 3-4 | BO32: 500-700 | BP32: 2000-5000 | BQ32: Acopiador | BR32: 4-5 | BS32: Espinel | BT32: 4 | BU32: 30-50 | BV32: Peruana y Extranjera | BW32: Perico | BX32: si, volador | BY32: Noviembre-Diciembre | BZ32: 4-5 | CA32: Linea madre: 13500 metros. #anzuelos: 1500. 1 anzuelo/linea. Calibre: 2 | CB32: 8-10 | CC32: 2-3 | CD32: 3-4 | CE32: 500-700 | CF32: 2000-5000 | CG32: Acopiador | CH32: 10-11 | CI32: Cortina Superficial | CJ32: Bonito | CK32: no | CL32: Septiembre-Abril | CM32: 35-40 | CN32: #paños: 10, cocada: 4 pulgadas, malla 6.75 x 4.5 m | CO32: 4 | CP32: 2 | CQ32: 3-4 | CR32: 200-400 | CS32: 4000-5000 | CT32: Acopiador | CU32: 1.5-4 | CV32: Zona: Perico (80-100 millas fuera de Callao y Marcona); Bonito (40-50 millas fuera de Pucusana). | CW32: 917 809 029
A33: KD-PUCUSANA-032 | B33: Kelly Diaz | C33: 45888 | D33: Yossimar Gonzales Peña | E33: 47606441 | F33: 21 | G33: 18 | H33: Pucusana | I33: Pucusana | J33: Pucusana, Callao | K33: 33109 | L33: =DATEDIF(K33, DATE(2025,8,29), "Y") -> 35 | M33: M | N33: Casado/Conviviente | O33: Secundaria | P33: si | Q33: si | R33: Armador | S33: no | T33: NA | U33: si | V33: Cortina costera | W33: pejerrey, jurel, caballa | X33: NA | Y33: NA | Z33: NA | AA33: NA | AB33: no | AC33: NA | AD33: 3 | AE33: 2 | AF33: si | AG33: Ama de casa | AH33: no | AI33: NA | AJ33: si | AK33: NA | AL33: si | AM33: NA | AN33: 1 | AO33: si | AP33: RIHANNA AILANI | AQ33: PS-18637-BM | AR33: no | AS33: no | AT33: si | AU33: 6 | AV33: NA | AW33: NA | AX33: NA | AY33: NA | AZ33: NA | BA33: NA | BB33: 8-24 | BC33: Cortina superficial | BD33: 4 | BE33: 30-40 | BF33: Peruana | BG33: Bonito | BH33: no | BI33: Septiembre-Abril | BJ33: 25-30 | BK33: #paños: 8-9, cocada: 4-4.5 pulgadas, malla 5 x 150 m | BL33: 7 | BM33: 2 | BN33: 3 | BO33: 200-1000 | BP33: 1000-2000 | BQ33: Acopiador | BR33: 1.5-2.1 | BS33: Trampa Ovas | BT33: 3 | BU33: 30-40 | BV33: Peruana | BW33: Ova | BX33: no | BY33: Septiembre-Diciembre | BZ33: 3 | CA33: Esteras y manta, con palmeras. Usa 12 trampas. Dimensiones de trampa 2x3 metros | CB33: 30-40 | CC33: 72 | CD33: 10-12 | CE33: 20-150 | CF33: 1000 | CG33: Acopiador | CH33: 30-40 | CI33: NA | CJ33: NA | CK33: NA | CL33: NA | CM33: NA | CN33: NA | CO33: NA | CP33: NA | CQ33: NA | CR33: NA | CS33: NA | CT33: NA | CU33: NA | CV33: Zona: Bonito (20-60 millas fuera de Pucusana); Ova (100 millas fuera de Marcona). Precio (kg) de ova con ojo: 5-10 soles. Por dia, botan al agua 3 trampas. La palmera dura 1 mes, la manguera dura 1 año; el zargazo dura 3 usos. Recientemente estan usando la maya anaranjada (que se usa en pistas), dura 1 solo uso. | CW33: 932 015 678 | CX33: apagado | CY33: Ova (100 millas fuera de Marcona)
